Workbook

Sheet Summary
A2: Sold/Won | H2: Pipeline/Open SOWs
A3: Total Revenue Sold | B3: =SUMIF(Detail!$L$2:$L$269,"Won",Detail!$C$2:$C$269) -> 2515489 | D3: Win % | E3: =B6/SUM(F22:F23) -> 0.41025641 | H3: Total Open Rev | I3: =SUMIF(Detail!$L$2:$L$269,"Out For Signature",Detail!$C$2:$C$269) -> 410843.8 | K3: Open | L3: Rev | O3: Signed by Month
A4: Total GP | B4: =SUMIF(Detail!$L$2:$L$270,"Won",Detail!$E$2:$E$269) -> 733810.77 | D4: Avg Days to Sign | E4: =AVERAGEIFS(Table1[Days to Sign], Table1[Status], "Won") -> 151.72727 | H4: Total Open GP | I4: =SUMIF(Detail!$L$2:$L$270,"Out For Signature",Detail!$E$2:$E$269) -> 55343.124 | J4: Devan | K4: =COUNTIFS(Table1[Presales],J4,Table1[Status],"Out For Signature") -> 1 | L4: =SUMIFS(Detail!$C$2:$C$269,Detail!$K$2:$K$269,J4,Detail!$L$2:$L$269,"Out For Signature") -> 62490 | O4: Dec | P4: =SUMIFS(Table1[Rev],Table1[Date Signed],">=01-Dec-2023",Table1[Date Signed],"<=31-Dec-2023",Table1[Status],"Won") -> 0
A5: Total GP % | B5: =B4/B3 -> 0.29171695 | D5: Lost Opps | E5: =COUNTIF(Table1[Status],"Lost") -> 0 | H5: Open GP % | I5: =I4/I3 -> 0.134706 | J5: Steve | K5: =COUNTIFS(Table1[Presales],J5,Table1[Status],"Out For Signature") -> 5 | L5: =SUMIFS(Detail!$C$2:$C$269,Detail!$K$2:$K$269,J5,Detail!$L$2:$L$269,"Out For Signature") -> 92985.8 | O5: Jan | P5: =SUMIFS(Table1[Rev],Table1[Date Signed],">=01-Jan-2024",Table1[Date Signed],"<=31-Jan-2024",Table1[Status],"Won") -> 0
A6: Total Won Opps | B6: =COUNTIF(Table1[Status],"Won") -> 16 | D6: Loss % | E6: =E5/SUM(F22:F23) -> 0 | H6: Total Open SOWs | I6: =COUNTIF(Table1[Status],"Out For Signature") -> 7 | O6: Feb | P6: =SUMIFS(Table1[Rev],Table1[Date Signed],">=01-Feb-2024",Table1[Date Signed],"<=29-Feb-2024",Table1[Status],"Won") -> 0
A7: Avg Win Size | B7: =AVERAGEIF(Detail!$L$2:$L$269,"Won",Detail!$C$2:$C$269) -> 157218.06 | O7: Mar | P7: =SUMIFS(Table1[Rev],Table1[Date Signed],">=01-Mar-2024",Table1[Date Signed],"<=31-Mar-2024",Table1[Status],"Won") -> 0
A8: Practice Area | B8: Rev | C8: GP | D8: GP % | E8: Opps Sold | F8: Rev Share | H8: Practice Area | I8: Rev | J8: GP | K8: GP % | L8: Opps Open | O8: Apr | P8: =SUMIFS(Table1[Rev],Table1[Date Signed],">=01-Apr-2024",Table1[Date Signed],"<=30-Apr-2024",Table1[Status],"Won") -> 0
A9: Health Check | B9: =SUMIFS(Detail!$C$2:$C$269,Detail!$J$2:$J$269,A9,Detail!$L$2:$L$269,"Won") -> 0 | C9: =SUMIFS(Detail!$E$2:$E$269,Detail!$J$2:$J$269,A9,Detail!$L$2:$L$269,"Won") -> 0 | D9: =C9/B9 -> #DIV/0! | E9: =COUNTIFS(Table1[Practice Area],A9,Table1[Status],"Won") -> 0 | F9: =B9/$B$3 -> 0 | H9: Health Check | I9: =SUMIFS(Detail!$C$2:$C$269,Detail!$J$2:$J$269,H9,Detail!$L$2:$L$269,"Out for Signature") -> 0 | J9: =SUMIFS(Detail!$E$2:$E$269,Detail!$J$2:$J$269,H9,Detail!$L$2:$L$269,"Out for Signature") -> 0 | K9: =J9/I9 -> #DIV/0! | L9: =COUNTIFS(Table1[Practice Area],H9,Table1[Status],"Out For Signature") -> 0 | O9: May | P9: =SUMIFS(Table1[Rev],Table1[Date Signed],">=01-May-2024",Table1[Date Signed],"<=31-May-2024",Table1[Status],"Won") -> 0
A10: Platform Engineering | B10: =SUMIFS(Detail!$C$2:$C$269,Detail!$J$2:$J$269,A10,Detail!$L$2:$L$269,"Won") -> 101118 | C10: =SUMIFS(Detail!$E$2:$E$269,Detail!$J$2:$J$269,A10,Detail!$L$2:$L$269,"Won") -> 35405.68 | D10: =C10/B10 -> 0.35014221 | E10: =COUNTIFS(Table1[Practice Area],A10,Table1[Status],"Won") -> 4 | F10: =B10/$B$3 -> 0.040198148 | H10: Platform Engineering | I10: =SUMIFS(Detail!$C$2:$C$269,Detail!$J$2:$J$269,H10,Detail!$L$2:$L$269,"Out for Signature") -> 81000 | J10: =SUMIFS(Detail!$E$2:$E$269,Detail!$J$2:$J$269,H10,Detail!$L$2:$L$269,"Out for Signature") -> 30594.9 | K10: =J10/I10 -> 0.37771481 | L10: =COUNTIFS(Table1[Practice Area],H10,Table1[Status],"Out For Signature") -> 2 | O10: Jun | P10: =SUMIFS(Table1[Rev],Table1[Date Signed],">=01-Jun-2024",Table1[Date Signed],"<=30-Jun-2024",Table1[Status],"Won") -> 0
A11: Migration | B11: =SUMIFS(Detail!$C$2:$C$269,Detail!$J$2:$J$269,A11,Detail!$L$2:$L$269,"Won") -> 2260130 | C11: =SUMIFS(Detail!$E$2:$E$269,Detail!$J$2:$J$269,A11,Detail!$L$2:$L$269,"Won") -> 642511.25 | D11: =C11/B11 -> 0.28428066 | E11: =COUNTIFS(Table1[Practice Area],A11,Table1[Status],"Won") -> 4 | F11: =B11/$B$3 -> 0.89848534 | H11: Migration | I11: =SUMIFS(Detail!$C$2:$C$269,Detail!$J$2:$J$269,H11,Detail!$L$2:$L$269,"Out for Signature") -> 0 | J11: =SUMIFS(Detail!$E$2:$E$269,Detail!$J$2:$J$269,H11,Detail!$L$2:$L$269,"Out for Signature") -> 0 | K11: =J11/I11 -> #DIV/0! | L11: =COUNTIFS(Table1[Practice Area],H11,Table1[Status],"Out For Signature") -> 0 | O11: Jul | P11: =SUMIFS(Table1[Rev],Table1[Date Signed],">=01-Jul-2024",Table1[Date Signed],"<=29-Jul-2024",Table1[Status],"Won") -> 0
A12: ASAM | B12: =SUMIFS(Detail!$C$2:$C$269,Detail!$J$2:$J$269,A12,Detail!$L$2:$L$269,"Won") -> 36680 | C12: =SUMIFS(Detail!$E$2:$E$269,Detail!$J$2:$J$269,A12,Detail!$L$2:$L$269,"Won") -> 13348 | D12: =C12/B12 -> 0.36390403 | E12: =COUNTIFS(Table1[Practice Area],A12,Table1[Status],"Won") -> 2 | F12: =B12/$B$3 -> 0.014581658 | H12: ASAM | I12: =SUMIFS(Detail!$C$2:$C$269,Detail!$J$2:$J$269,H12,Detail!$L$2:$L$269,"Out for Signature") -> 34000 | J12: =SUMIFS(Detail!$E$2:$E$269,Detail!$J$2:$J$269,H12,Detail!$L$2:$L$269,"Out for Signature") -> 12920 | K12: =J12/I12 -> 0.38 | L12: =COUNTIFS(Table1[Practice Area],H12,Table1[Status],"Out For Signature") -> 2 | O12: Aug | P12: =SUMIFS(Table1[Rev],Table1[Date Signed],">=01-Aug-2024",Table1[Date Signed],"<=31-Aug-2024",Table1[Status],"Won") -> 0
A13: Security | B13: =SUMIFS(Detail!$C$2:$C$269,Detail!$J$2:$J$269,A13,Detail!$L$2:$L$269,"Won") -> 0 | C13: =SUMIFS(Detail!$E$2:$E$269,Detail!$J$2:$J$269,A13,Detail!$L$2:$L$269,"Won") -> 0 | D13: =C13/B13 -> #DIV/0! | E13: =COUNTIFS(Table1[Practice Area],A13,Table1[Status],"Won") -> 0 | F13: =B13/$B$3 -> 0 | H13: Security | I13: =SUMIFS(Detail!$C$2:$C$269,Detail!$J$2:$J$269,H13,Detail!$L$2:$L$269,"Out for Signature") -> 0 | J13: =SUMIFS(Detail!$E$2:$E$269,Detail!$J$2:$J$269,H13,Detail!$L$2:$L$269,"Out for Signature") -> 0 | K13: =J13/I13 -> #DIV/0! | L13: =COUNTIFS(Table1[Practice Area],H13,Table1[Status],"Out For Signature") -> 0 | O13: Sep | P13: =SUMIFS(Table1[Rev],Table1[Date Signed],">=01-Sep-2024",Table1[Date Signed],"<=30-Sep-2024",Table1[Status],"Won") -> 0
A14: Landing Zone | B14: =SUMIFS(Detail!$C$2:$C$270,Detail!$J$2:$J$270,A14,Detail!$L$2:$L$270,"Won") -> 69769 | C14: =SUMIFS(Detail!$E$2:$E$269,Detail!$J$2:$J$269,A14,Detail!$L$2:$L$269,"Won") -> 25116.84 | D14: =C14/B14 -> 0.36 | E14: =COUNTIFS(Table1[Practice Area],A14,Table1[Status],"Won") -> 2 | F14: =B14/$B$3 -> 0.02773576 | H14: Landing Zone | I14: =SUMIFS(Detail!$C$2:$C$269,Detail!$J$2:$J$269,H14,Detail!$L$2:$L$269,"Out for Signature") -> 0 | J14: =SUMIFS(Detail!$E$2:$E$269,Detail!$J$2:$J$269,H14,Detail!$L$2:$L$269,"Out for Signature") -> 0 | K14: =J14/I14 -> #DIV/0! | L14: =COUNTIFS(Table1[Practice Area],H14,Table1[Status],"Out For Signature") -> 0 | O14: Oct | P14: =SUMIFS(Table1[Rev],Table1[Date Signed],">=01-Oct-2024",Table1[Date Signed],"<=31-Oct-2024",Table1[Status],"Won") -> 0
A15: BCDR | B15: =SUMIFS(Detail!$C$2:$C$270,Detail!$J$2:$J$270,A15,Detail!$L$2:$L$270,"Won") -> 13096 | C15: =SUMIFS(Detail!$E$2:$E$269,Detail!$J$2:$J$269,A15,Detail!$L$2:$L$269,"Won") -> 4976.48 | D15: =C15/B15 -> 0.38 | E15: =COUNTIFS(Table1[Practice Area],A15,Table1[Status],"Won") -> 1 | F15: =B15/$B$3 -> 0.0052061448 | H15: BCDR | I15: =SUMIFS(Detail!$C$2:$C$269,Detail!$J$2:$J$269,H15,Detail!$L$2:$L$269,"Out for Signature") -> 0 | J15: =SUMIFS(Detail!$E$2:$E$269,Detail!$J$2:$J$269,H15,Detail!$L$2:$L$269,"Out for Signature") -> 0 | K15: =J15/I15 -> #DIV/0! | L15: =COUNTIFS(Table1[Practice Area],H15,Table1[Status],"Out For Signature") -> 0 | O15: Nov | P15: =SUMIFS(Table1[Rev],Table1[Date Signed],">=01-Nov-2024",Table1[Date Signed],"<=30-Nov-2024",Table1[Status],"Won") -> 0
A16: Bucket of Hours | B16: =SUMIFS(Detail!$C$2:$C$270,Detail!$J$2:$J$270,A16,Detail!$L$2:$L$270,"Won") -> 5500 | C16: =SUMIFS(Detail!$E$2:$E$269,Detail!$J$2:$J$269,A16,Detail!$L$2:$L$269,"Won") -> 2035 | D16: =C16/B16 -> 0.37 | E16: =COUNTIFS(Table1[Practice Area],A16,Table1[Status],"Won") -> 1 | F16: =B16/$B$3 -> 0.0021864536 | H16: Bucket of Hours | I16: =SUMIFS(Detail!$C$2:$C$269,Detail!$J$2:$J$269,H16,Detail!$L$2:$L$269,"Out For Signature") -> 40475.8 | J16: =SUMIFS(Detail!$E$2:$E$269,Detail!$J$2:$J$269,H16,Detail!$L$2:$L$269,"Out For Signature") -> 11828.224 | K16: =J16/I16 -> 0.29222953 | L16: =COUNTIFS(Table1[Practice Area],H16,Table1[Status],"Out For Signature") -> 2 | O16: Dec | P16: =SUMIFS(Table1[Rev],Table1[Date Signed],">=01-Dec-2024",Table1[Date Signed],"<=31-Dec-2024",Table1[Status],"Won") -> 0
A17: Cost Optimization | B17: =SUMIFS(Detail!$C$2:$C$272,Detail!$J$2:$J$272,"Teams Rooms",Detail!$L$2:$L$272,"Won") -> 0 | C17: =SUMIFS(Detail!$E$2:$E$269,Detail!$J$2:$J$269,"Teams Rooms",Detail!$L$2:$L$269,"Won") -> 0 | D17: =C17/B17 -> #DIV/0! | E17: =COUNTIFS(Table1[Practice Area],"Teams Rooms",Table1[Status],"Won") -> 0 | F17: =B17/$B$3 -> 0 | H17: Cost Optimization | I17: =SUMIFS(Detail!$C$2:$C$269,Detail!$J$2:$J$269,H17,Detail!$L$2:$L$269,"Out For Signature") -> 0 | J17: =SUMIFS(Detail!$E$2:$E$269,Detail!$J$2:$J$269,H17,Detail!$L$2:$L$269,"Out For Signature") -> 0 | K17: =J17/I17 -> #DIV/0!
A20: Presales | I20: Deal Size Stats
B21: SOWs Won | C21: Rev Sold | D21: GP Sold | E21: GP % Sold | F21: SOWs Written | G21: Close Rate | J21: Scoped | K21: Signed | L21: Rev Signed | M21: GP
A22: Devan | B22: =COUNTIFS(Table1[Presales],A22,Table1[Status],"Won") -> 1 | C22: =SUMIFS(Detail!$C$2:$C$269,Detail!$K$2:$K$269,A22,Detail!$L$2:$L$269,"Won") -> 5500 | D22: =SUMIFS(Detail!$E$2:$E$269,Detail!$K$2:$K$269,A22,Detail!$L$2:$L$269,"Won") -> 1650 | E22: =D22/C22 -> 0.3 | F22: =COUNTIF(Table1[Presales],A22) -> 6 | G22: =B22/F22 -> 0.16666667 | I22: Under $10,000 | J22: =COUNTIF(Table1[Rev],"<9999") -> 5 | K22: =COUNTIFS(Table1[Rev],"<9999",Table1[Status],"Won") -> 4 | L22: =SUMIFS(Table1[Rev],Table1[Rev],"<9999",Table1[Status],"Won") -> 21000 | M22: =SUMIFS(Table1[GP $],Table1[Rev],"<9999",Table1[Status],"Won") -> 6685
A23: Steve | B23: =COUNTIFS(Table1[Presales],A23,Table1[Status],"Won") -> 15 | C23: =SUMIFS(Detail!$C$2:$C$269,Detail!$K$2:$K$269,A23,Detail!$L$2:$L$269,"Won") -> 2509989 | D23: =SUMIFS(Detail!$E$2:$E$269,Detail!$K$2:$K$269,A23,Detail!$L$2:$L$269,"Won") -> 732160.77 | E23: =D23/C23 -> 0.2916988 | F23: =COUNTIF(Table1[Presales],A23) -> 33 | G23: =B23/F23 -> 0.45454545 | I23: $10,000 --> $24,999 | J23: =COUNTIFS(Table1[Rev],">9999",Table1[Rev],"<25000") -> 7 | K23: =COUNTIFS(Table1[Rev],">9999",Table1[Rev],"<24999",Table1[Status],"Won") -> 4 | L23: =SUMIFS(Table1[Rev],Table1[Rev],">9999",Table1[Rev],"<24999",Table1[Status],"Won") -> 73472 | M23: =SUMIFS(Table1[GP $],Table1[Rev],">9999",Table1[Rev],"<24999",Table1[Status],"Won") -> 27092
A24: Chris | B24: =COUNTIFS(Table1[Presales],A24,Table1[Status],"Won") -> 0 | C24: =SUMIFS(Detail!$C$2:$C$269,Detail!$K$2:$K$269,A24,Detail!$L$2:$L$269,"Won") -> 0 | D24: =SUMIFS(Detail!$E$2:$E$269,Detail!$K$2:$K$269,A24,Detail!$L$2:$L$269,"Won") -> 0 | E24: =D24/C24 -> #DIV/0! | F24: =COUNTIF(Table1[Presales],A24) -> 0 | G24: =B24/F24 -> #DIV/0! | I24: $25,000 --> $99,999 | J24: =COUNTIFS(Table1[Rev],">25000",Table1[Rev],"<100000") -> 6 | K24: =COUNTIFS(Table1[Rev],">24999",Table1[Rev],"<99999",Table1[Status],"Won") -> 4 | L24: =SUMIFS(Table1[Rev],Table1[Rev],">25000",Table1[Rev],"<99999",Table1[Status],"Won") -> 160887 | M24: =SUMIFS(Table1[GP $],Table1[Rev],">25000",Table1[Rev],"<99999",Table1[Status],"Won") -> 57522.52
I25: $100,000 + | J25: =COUNTIF(Table1[Rev],">99999") -> 6 | K25: =COUNTIFS(Table1[Rev],">99999",Table1[Status],"Won") -> 4 | L25: =SUMIFS(Table1[Rev],Table1[Rev],">99999",Table1[Status],"Won") -> 2260130 | M25: =SUMIFS(Table1[GP $],Table1[Rev],">99999",Table1[Status],"Won") -> 642511.25

Sheet Detail
A1: Date Signed | B1: Hours | C1: Rev | D1: GP % | E1: GP $ | F1: Qorus Opp | G1: Client | H1: Project Name | I1: Resource(s) | J1: Practice Area | K1: Presales | L1: Status | M1: Tech Approval | N1: Days to Sign | O1: AE | P1: Overall Rev | Q1: Overall GP | R1: Comment
A2: 45952 | B2: 62 | C2: 17000 | D2: 0.38 | E2: =Table1[[#This Row],[Rev]]*Table1[[#This Row],[GP %]] -> 6460 | F2: 5010000962 | G2: Wolf | H2: ASAM | I2: Brendan, Onome | J2: ASAM | K2: Steve | L2: Won | M2: 45939 | N2: =Table1[[#This Row],[Date Signed]]-Table1[[#This Row],[Tech Approval]] -> 13 | O2: Jodie Faringside
B3: 120 | C3: 29668 | D3: 0.36 | E3: =Table1[[#This Row],[Rev]]*Table1[[#This Row],[GP %]] -> 10680.48 | F3: 5010001071 | G3: Kids Ability | H3: Landing Zone | I3: Artem, Joe | J3: Landing Zone | K3: Steve | L3: Won | M3: 45945 | N3: =Table1[[#This Row],[Date Signed]]-Table1[[#This Row],[Tech Approval]] -> -45945 | O3: Rebekah Guanlao | R3: Need to follow up with the Account Executive.
A4: 46317 | B4: 45 | C4: 13096 | D4: 0.38 | E4: =Table1[[#This Row],[Rev]]*Table1[[#This Row],[GP %]] -> 4976.48 | F4: 4010102646 | G4: Lantic | H4: Backup RPO | I4: Joe | J4: BCDR | K4: Steve | L4: Won | M4: 45945 | N4: =Table1[[#This Row],[Date Signed]]-Table1[[#This Row],[Tech Approval]] -> 372 | O4: Stephane Lourenco
C5: 62490 | D5: 0.38 | E5: =Table1[[#This Row],[Rev]]*Table1[[#This Row],[GP %]] -> 23746.2 | F5: 5010000600 | G5: Novatel | H5: Multi-Cloud Gap Assessment | I5: Brendan, Joe | J5: Platform Engineering | K5: Devan | L5: Out for Signature | M5: 45915 | N5: =Table1[[#This Row],[Date Signed]]-Table1[[#This Row],[Tech Approval]] -> -45915 | O5: Chris Mckenzie
A6: 46352 | C6: 23696 | D6: 0.37 | E6: =Table1[[#This Row],[Rev]]*Table1[[#This Row],[GP %]] -> 8767.52 | F6: 4010103179 | G6: Equisoft | H6: AWS Cost Optimization | I6: Brett | J6: AWS | K6: Steve | L6: Won | M6: 45924 | N6: =Table1[[#This Row],[Date Signed]]-Table1[[#This Row],[Tech Approval]] -> 428 | O6: Maxime Deguire
C7: 40101 | D7: 0.36 | E7: =Table1[[#This Row],[Rev]]*Table1[[#This Row],[GP %]] -> 14436.36 | F7: 5010000673 | G7: LTI Mindtree | H7: Azure Landing Zone | I7: Artem, Joe | J7: Landing Zone | K7: Steve | L7: Won | M7: 45965 | N7: =Table1[[#This Row],[Date Signed]]-Table1[[#This Row],[Tech Approval]] -> -45965 | O7: TBD
A8: 46290 | C8: 51438 | D8: 0.36 | E8: =Table1[[#This Row],[Rev]]*Table1[[#This Row],[GP %]] -> 18517.68 | F8: 4010102985 | G8: Eclipse | H8: Azure Tenant Move | I8: Brendan | J8: Platform Engineering | K8: Steve | L8: Won | M8: 46288 | N8: =Table1[[#This Row],[Date Signed]]-Table1[[#This Row],[Tech Approval]] -> 2 | O8: Abhishek Baghel
A9: 45917 | C9: 154529 | D9: 0.37 | E9: =Table1[[#This Row],[Rev]]*Table1[[#This Row],[GP %]] -> 57175.73 | F9: 5010000241 | G9: IAMGOLD | H9: Azure Migration | I9: Josh, Onome | J9: Migration | K9: Steve | L9: Won | M9: 45911 | N9: =Table1[[#This Row],[Date Signed]]-Table1[[#This Row],[Tech Approval]] -> 6 | O9: Alok Khant
A10: 45894 | C10: 106465 | D10: 0.32 | E10: =Table1[[#This Row],[Rev]]*Table1[[#This Row],[GP %]] -> 34068.8 | F10: 4010098895 | G10: Amphenol | H10: Azure Migration | I10: Artem, Onome | J10: Migration | K10: Steve | L10: Won | M10: 45863 | N10: =Table1[[#This Row],[Date Signed]]-Table1[[#This Row],[Tech Approval]] -> 31 | O10: Abhishek Baghel
C11: 39680 | D11: 0.35 | E11: =Table1[[#This Row],[Rev]]*Table1[[#This Row],[GP %]] -> 13888 | F11: 5010003238 | G11: Venterra | H11: Eva AI Migration and Front End | I11: Brett, Ryan | J11: Platform Engineering | K11: Steve | L11: Won | N11: =Table1[[#This Row],[Date Signed]]-Table1[[#This Row],[Tech Approval]] -> 0
A12: 46366 | C12: 5000 | D12: 0.3 | E12: =Table1[[#This Row],[Rev]]*Table1[[#This Row],[GP %]] -> 1500 | G12: Deltera | H12: Bucket of Hours | I12: Artem | J12: Platform Engineering | K12: Steve | L12: Won | N12: =Table1[[#This Row],[Date Signed]]-Table1[[#This Row],[Tech Approval]] -> 46366
A13: 46361 | C13: 5000 | D13: 0.3 | E13: =Table1[[#This Row],[Rev]]*Table1[[#This Row],[GP %]] -> 1500 | G13: Fournier et Fils | H13: Bucket of Hours | I13: Artem | J13: Platform Engineering | K13: Steve | L13: Won | N13: =Table1[[#This Row],[Date Signed]]-Table1[[#This Row],[Tech Approval]] -> 46361
B14: 62 | C14: 17000 | D14: 0.38 | E14: =Table1[[#This Row],[Rev]]*Table1[[#This Row],[GP %]] -> 6460 | F14: 5010004102 | G14: Ontario Science Center | H14: ASAM | I14: Joe | J14: ASAM | K14: Steve | L14: Out for Signature | M14: 46013 | N14: =Table1[[#This Row],[Date Signed]]-Table1[[#This Row],[Tech Approval]] -> -46013 | O14: Paula Eerdmans | R14: No updates, Steve to follow up
A15: 46036 | C15: 115000 | D15: 0.37 | E15: =Table1[[#This Row],[Rev]]*Table1[[#This Row],[GP %]] -> 42550 | F15: 5010003533 | G15: PayFacto | H15: Azure VMware Solution | I15: TBD | J15: Migration | K15: Steve | L15: Won | M15: 46374 | O15: Paula Eerdmans | R15: Paula sent an email to the customer.
A16: 46339 | C16: 19680 | D16: 0.35 | E16: =Table1[[#This Row],[Rev]]*Table1[[#This Row],[GP %]] -> 6888 | F16: 5010000594 | G16: Metro Supply Group | H16: Azure Local - ASAM | I16: Brendan | J16: ASAM | K16: Steve | L16: Won | M16: 46290
A17: 46039 | C17: 5500 | D17: 0.37 | E17: =Table1[[#This Row],[Rev]]*Table1[[#This Row],[GP %]] -> 2035 | F17: 5010003897 | G17: Mount Pleasant Group of Cemeteries | H17: Bucket of Hours | I17: Omer | J17: Bucket of Hours | K17: Steve | L17: Won | M17: 46034 | O17: Robert Groome
A18: 46044 | C18: 1884136 | D18: 0.27 | E18: =Table1[[#This Row],[Rev]]*Table1[[#This Row],[GP %]] -> 508716.72 | F18: 5010003160 | G18: Ovintiv | H18: Cloud Migration | I18: Artem, Ryan | J18: Migration | K18: Steve | L18: Won | M18: 46043 | O18: Kay Bank
C19: 17000 | D19: 0.38 | E19: =Table1[[#This Row],[Rev]]*Table1[[#This Row],[GP %]] -> 6460 | F19: 5010004572 | G19: Maxims | H19: ASAM | I19: TBD | J19: ASAM | K19: Steve | L19: Out for Signature | M19: 46036 | O19: Paula Eerdmans | R19: Docusign workflow soon
E20: =Table1[[#This Row],[Rev]]*Table1[[#This Row],[GP %]] -> 0 | G20: Eclipse CR | K20: Steve | L20: Dead | R20: Ryan is talking to the client with Sheila
E21: =Table1[[#This Row],[Rev]]*Table1[[#This Row],[GP %]] -> 0 | F21: 5010003423 | G21: Orbcomm | H21: Azure Firewall Implementation | L21: Dead | R21: Devan redirected back to Steve for review
E22: =Table1[[#This Row],[Rev]]*Table1[[#This Row],[GP %]] -> 0 | G22: KDC | H22: Azure Landing Zone | J22: Landing Zone | K22: Steve | L22: Scoping | R22: Microsoft is still educating customer on Landing Zone.
A23: 46034 | C23: 5500 | D23: 0.3 | E23: =Table1[[#This Row],[Rev]]*Table1[[#This Row],[GP %]] -> 1650 | G23: Mevotech | H23: Bucket of Hours | K23: Devan | L23: Won | M23: 46365 | O23: Erin Wallace | R23: Sent proposal.
C24: 5500 | D24: 0.37 | E24: =Table1[[#This Row],[Rev]]*Table1[[#This Row],[GP %]] -> 2035 | F24: 5010002500 | G24: ASS De La Const Du Que | H24: Bucket of Hours | J24: Bucket of Hours | K24: Steve | L24: Out for Signature | R24: Blob for veeam backup repository. Steve to find out if there is a contract number.
E25: =Table1[[#This Row],[Rev]]*Table1[[#This Row],[GP %]] -> 0 | F25: 4010085595 | G25: CentreCorp | K25: Steve | L25: Dead | R25: Alex (AE) was talking to VP of IT. Workflow had been cancelled but oppt still there.
E26: =Table1[[#This Row],[Rev]]*Table1[[#This Row],[GP %]] -> 0 | G26: Le Groupe Master | K26: Steve | L26: Scoping | R26: Dan is going to chat with them at EBC
E27: =Table1[[#This Row],[Rev]]*Table1[[#This Row],[GP %]] -> 0 | G27: North River Midstream | J27: Platform Engineering | K27: Josh | L27: Scoping | R27: Josh has created a quick proposal, no SOW yet
C28: 255368 | E28: =Table1[[#This Row],[Rev]]*Table1[[#This Row],[GP %]] -> 0 | F28: 5010001895 | G28: Graham | H28: Azure to AWS Migration Project | J28: AWS | K28: Ravin | L28: Out for Signature | R28: Meeting with Nick/Dave around this on Friday.
E29: =Table1[[#This Row],[Rev]]*Table1[[#This Row],[GP %]] -> 0 | G29: Powerex | H29: GitHub Copilot | K29: Devan
E30: =Table1[[#This Row],[Rev]]*Table1[[#This Row],[GP %]] -> 0 | G30: OCIL | H30: Storage Account | J30: AWS | K30: Brett | L30: Dead | R30: Devan to follow up with Jamie
C31: 34975.8 | D31: 0.28 | E31: =Table1[[#This Row],[Rev]]*Table1[[#This Row],[GP %]] -> 9793.224 | F31: 5010004388 | G31: Gibson | H31: Bucket of Hours (Josh) | I31: Josh Geck | J31: Bucket of Hours | K31: Steve | L31: Out for Signature | M31: 46030 | O31: Michael Mckenzie | R31: PO is on the way
E32: =Table1[[#This Row],[Rev]]*Table1[[#This Row],[GP %]] -> 0 | G32: Mcard | H32: Followup to a WAFR that we did for them | J32: AWS | K32: Ravin | L32: Scoping | R32: Waiting on customer questionnaire.
E33: =Table1[[#This Row],[Rev]]*Table1[[#This Row],[GP %]] -> 0 | G33: Gibson | H33: HCI Migration | J33: Migration | K33: Steve | L33: Scoping
E34: =Table1[[#This Row],[Rev]]*Table1[[#This Row],[GP %]] -> 0 | G34: GoA | H34: Azure Site Recovery | K34: Devan
E35: =Table1[[#This Row],[Rev]]*Table1[[#This Row],[GP %]] -> 0 | G35: SPG | H35: VM Migration | J35: Migration | K35: Steve | L35: Scoping | R35: Proposal has been sent out
C36: 25000 | E36: =Table1[[#This Row],[Rev]]*Table1[[#This Row],[GP %]] -> 0 | G36: Davis Ward (DWPV) | H36: Azure FinOps | J36: Cost Optimization | K36: Ravin | L36: Scoping | O36: Paul Anon | R36: Sent proposal to client. Potential funding available?
E37: =Table1[[#This Row],[Rev]]*Table1[[#This Row],[GP %]] -> 0 | G37: Mohawk Council Of Akwesasne | H37: Landing Zone | J37: Bucket of Hours | K37: Steve | L37: Scoping | O37: Paula Eerdmans | R37: Bucket of hours has been sent for VMware stuff
E38: =Table1[[#This Row],[Rev]]*Table1[[#This Row],[GP %]] -> 0 | G38: QPS | H38: Azure Files Migration | J38: Platform Engineering | K38: Steve | L38: Scoping | O38: Alok Khant | R38: Meeting with them in February
C39: 132000 | E39: =Table1[[#This Row],[Rev]]*Table1[[#This Row],[GP %]] -> 0 | G39: Kingston Midstream | H39: Databricks | J39: Platform Engineering | K39: Devan/Dan | L39: Scoping | R39: Proposal has been sent out
E40: =Table1[[#This Row],[Rev]]*Table1[[#This Row],[GP %]] -> 0 | G40: Orbcomm | H40: Tenant Fabric Move | K40: Ravin | L40: Scoping | R40: Dan has the tenant portion incorporated into our SOW.
...
